<?xml version="1.0" ?>
<!--simple pbot-->

<robot name="SPBot">
    <link name="base_link">
    </link>
    <link name="link0">
        <inertial>
            <origin xyz="0.35 0.0 0.0" rpy="0 0 0" />
            <mass value="2" />
            <inertia ixx="0.01" iyy="0.01" izz="0.01" ixy="0" ixz="0" iyz="0" />
        </inertial>
        <visual>
            <origin xyz="0.0 0.0 0.0" rpy="0 0 0" />
            <geometry>
                <sphere radius="0.05" />
            </geometry>
            <material name="material_orange">
                <color rgba="0.8 0.6 0.2 1.0" />
            </material>
        </visual>
        <visual>
            <origin xyz="0.3 0.0 0.0" rpy="0 0 0" />
            <geometry>
                <box size="0.6 0.02 0.02" />
            </geometry>
            <material name="material_orange">
                <color rgba="0.8 0.6 0.2 1.0" />
            </material>
        </visual>
    </link>
    <link name="link1">
        <inertial>
            <origin xyz="0.35 0.0 0.0" rpy="0 0 0" />
            <mass value="10" />
            <inertia ixx="0.1" iyy="0.1" izz="0.1" ixy="0" ixz="0" iyz="0" />
        </inertial>
        <visual>
            <origin xyz="0.15 0.0 0.0" rpy="0 0 0" />
            <geometry>
                <box size="0.6 0.05 0.05" />
            </geometry>
            <material name="material_orange">
                <color rgba="0.8 0.6 0.2 1.0" />
            </material>
        </visual>
        <visual>
            <origin xyz="0.35 0.0 0.0" rpy="0 0 0" />
            <geometry>
                <sphere radius="0.15" />
            </geometry>
            <material name="material_orange">
                <color rgba="0.8 0.6 0.2 1.0" />
            </material>
        </visual>
        <collision>
            <origin xyz="0.35 0.0 0.0" rpy="0 0 0" />
            <geometry>
                <sphere radius="0.15" />
            </geometry>
        </collision>
    </link>

    <joint name="j0" type="spherical">
        <parent link="base_link" />
        <child link="link0" />
        <origin xyz="0.000000 0.000000 0.000000" rpy="-0.000000 0.000000 -0.000000" />
    </joint>
    <joint name="j1" type="prismatic">
        <parent link="link0" />
        <child link="link1" />
        <origin xyz="0.350000 0.000000 0.000000" rpy="-0.000000 0.000000 -0.000000" />
        <axis xyz="1 0 0" />
        <limit lower="-2.967" upper="2.967" effort="176" velocity="1.7104" />
    </joint>
    
</robot>



